<!--
 * @Descripttion:  
 * @Author: etong
 * @Date: 2021-07-09 16:12:18
 * @LastEditors: WangQi
 * @LastEditTime: 2021-07-12 13:58:56
-->

<!DOCTYPE html>
<html lang="en">

<head>
  <meta charset="UTF-8">
  <title>了解promise对象</title>
</head>

<body>
  <script>
    /* function timeout(ms){
      return new Promise((resolve, reject)=>{
        setTimeout(resolve, ms, 'done')
      })
    }
    timeout(100).then((value) =>{
      console.log(value)
    })

    // 新建后立即执行
    let promise = new Promise(function(resolve, reject){
      console.log('Promise')
      resolve()
    })
    promise.then(function(){ // then方法指定的回调函数，将在当前脚本所有同步任务执行完才会执行
      console.log('resolved')
    })
    console.log('Hi!') 
    // Promise Hi! resolved done 

    //异步加载图片
    function loadImageAsync(url){
      return new Promise(function(resolve, reject){
        const image = new Image()
        image.onload = function(){
          resolve(image)
        }
        image.onerror = function(){
          reject(new Error('Could not load image at '+ url))
        }
        image.src = url
      })
    } */

    // Promise对象实现的 Ajax
    /* const getJSON = function(url){
      const promise = new Promise(function(resolve, reject){
        const handler = function(){
          if(this.readyState !==4 ){
            return;
          }
          if(this.status === 200){
            resolve(this.response)
          } else {
            reject(new Error(this.statusText))
          }
        }
        const client = new XMLHttpRequest();
        client.open("GET", url)
        client.onreadystatechange = handler;
        client.responseType = "json";
        client.setRequestHeader("Accept", "application/json")
        client.send()
      })
      return promise;
    }
    getJSON("/posts.json").then(function(json){
      console.log('Contents: ' + json)
    }, function(error){
      console.error('出错了', error)
    })
 */
    // p1和p2 都是promise的实例，p2的resolve方法将p1作为参数，即一个异步操作的结果是返回另一个异步操作
    /* const p1 = new Promise(function(resolve, reject){
      setTimeout(()=> reject(new Error('fail')),3000)
    })
    const p2 = new Promise(function(resolve, reject){
      setTimeout(() => resolve(p1),1000)
    })
    p2
    .then(result => console.log(result))
    .catch(error => console.log(error))
 */
  /* const someAsyncThing = function(){
    return new Promise(function(resolve, reject){
      resolve(x + 2) // 会报错，因为x没有声明
    })
  } */
  // catch()方法抛出一个错误，因为后面没有别的catch()方法了，导致这个错误不会被捕获，也不会传递到外层。
  // oh no [ReferenceError: x is not defined]
  /* someAsyncThing().then(function(){
    return someAsyncThing()
  }).catch(function(error) {
    console.log('oh no', error);
    y + 2 //会报错，因为 y 没有声明
  }).then(function() {
    console.log('carry on')
  }) */
  // 第二个catch()方法用来捕获前一个catch()方法抛出的错误。
  // oh no [ReferenceError: x is not defined]
  // carry on [ReferenceError: y is not defined]
  /* someAsyncThing().then(function(){
    return someAsyncThing()
  }).catch(function(error){
    console.log('oh no', error);
    y + 2
  }).catch(function(error){
    console.log('crray on',error)
  }) */

  /* someAsyncThing().catch(function(error) {

    console.log('oh no', error)
  }).then(function(){
    console.log('carry on')
  }) */
  /* someAsyncThing().then(function() {
    console.log('everthing is great')
  }) 
  setTimeout(() => { console.log(123) },2000) */

  /* const promise = new Promise(function (resolve, reject){
    resolve('ok')
    setTimeout(function (){ throw new Error('test') },0)
  })
  promise.then(function (value) { console.log(value) }) */
  /* Promise.resolve().catch(function(error){
    console.log('oh no',error)
  }).then(function() {
    console.log('carry on')
  }) */

  // 由于作为参数的 Promise 实例，自己定义了catch方法，那么它一旦被rejected，并不会触发Promise.all()的catch方法
  // 把p2的catch方法去掉后，all里的catch会被触发 Error: 报错了
  /* const p1 = new Promise((resolve, reject)=>{
    resolve('hello')
  })
  .then(result => result)
  .catch(e => e)
  
  const p2 = new Promise(( resolve, reject) =>{
    throw new Error('报错啦')
  })
  .then(result => result)
  .catch(e => e)

  Promise.all([p1,p2])
  .then(result => console.log(result))
  .catch(e => console.log(e)) */

  // setTimeout(fn, 0)在下一轮“事件循环”开始时执行，
  // Promise.resolve()在本轮“事件循环”结束时执行，
  // console.log('one')则是立即执行，因此最先输出。
  setTimeout(function(){
    console.log('three')
  },0)
  Promise.resolve().then(function(){
    console.log('two')
  })
  console.log('one')
  
  </script>
</body>

</html>